2025-02-18 15:21:59,379 INFO    MainThread:13322 [wandb_setup.py:_flush():68] Current SDK version is 0.19.6
2025-02-18 15:21:59,379 INFO    MainThread:13322 [wandb_setup.py:_flush():68] Configure stats pid to 13322
2025-02-18 15:21:59,379 INFO    MainThread:13322 [wandb_setup.py:_flush():68] Loading settings from /home/t/.config/wandb/settings
2025-02-18 15:21:59,379 INFO    MainThread:13322 [wandb_setup.py:_flush():68] Loading settings from /home/t/workspace/AGI/THBI/sae_demo/wandb/settings
2025-02-18 15:21:59,379 INFO    MainThread:13322 [wandb_setup.py:_flush():68] Loading settings from environment variables
2025-02-18 15:21:59,379 INFO    MainThread:13322 [wandb_init.py:setup_run_log_directory():637] Logging user logs to /home/t/workspace/AGI/THBI/sae_demo/wandb/run-20250218_152159-uxjod44s/logs/debug.log
2025-02-18 15:21:59,380 INFO    MainThread:13322 [wandb_init.py:setup_run_log_directory():638] Logging internal logs to /home/t/workspace/AGI/THBI/sae_demo/wandb/run-20250218_152159-uxjod44s/logs/debug-internal.log
2025-02-18 15:21:59,380 INFO    MainThread:13322 [wandb_init.py:init():756] calling init triggers
2025-02-18 15:21:59,380 INFO    MainThread:13322 [wandb_init.py:init():761] wandb.init called with sweep_config: {}
config: {'learning_rate': 0.02, 'architecture': 'CNN', 'dataset': 'CIFAR-100', 'epochs': 10, '_wandb': {}}
2025-02-18 15:21:59,380 INFO    MainThread:13322 [wandb_init.py:init():789] starting backend
2025-02-18 15:21:59,584 INFO    MainThread:13322 [wandb_init.py:init():793] sending inform_init request
2025-02-18 15:21:59,593 INFO    MainThread:13322 [backend.py:_multiprocessing_setup():97] multiprocessing start_methods=fork,spawn,forkserver, using: spawn
2025-02-18 15:21:59,593 INFO    MainThread:13322 [wandb_init.py:init():808] backend started and connected
2025-02-18 15:21:59,596 INFO    MainThread:13322 [wandb_init.py:init():901] updated telemetry
2025-02-18 15:21:59,604 INFO    MainThread:13322 [wandb_init.py:init():936] communicating run to backend with 90.0 second timeout
2025-02-18 15:22:00,385 ERROR   MainThread:13322 [wandb_init.py:init():1481] error in wandb.init()
Traceback (most recent call last):
  File "/home/t/anaconda3/envs/sae/lib/python3.11/site-packages/wandb/sdk/wandb_init.py", line 1471, in init
    return wi.init(run_settings, run_config)
           ^^^^^^^^^^^^^^^^^^^^^^^^^^^^^^^^^
  File "/home/t/anaconda3/envs/sae/lib/python3.11/site-packages/wandb/sdk/wandb_init.py", line 967, in init
    raise error
wandb.errors.errors.CommError: failed to upsert bucket: returned error 403 Forbidden: {"errors":[{"message":"permission denied","path":["upsertBucket"],"extensions":{"code":"PERMISSION_ERROR"}}],"data":{"upsertBucket":null}}
2025-02-18 15:22:00,394 WARNING MsgRouterThr:13322 [router.py:message_loop():75] message_loop has been closed
